Workbook

Sheet How To Use
A1: HOW TO USE - SPC CALCULATOR v13
A2: Read this once. The charts need no macros; only folder monitoring does.
A4: QUICK START - NO MACROS NEEDED
A5: 1 | B5: Set up your features | C5: Settings sheet. For each feature type the name, Nominal, LSL, USL and unit, and set Active = Y. Yellow cells are the ones you edit.
A6: 2 | B6: Enter measurements | C6: Data Entry sheet. Column H is feature 1, I is feature 2, and so on. Date / Shift / Operator / Tool ID in columns C-F are optional but they are what the Visual SPC filters use.
A7: 3 | B7: Look at the charts | C7: Control Charts updates by itself - there is nothing to run. Each feature shows a statistics panel on the left, then the X chart, the moving-range chart and a histogram.
A8: 4 | B8: Check capability | C8: Capability sheet gives Cp, Cpk, Pp, Ppk with traffic lights, plus an in-control and an in-spec verdict per feature.
A9: 5 | B9: Filter and explore | C9: Visual SPC. Pick a feature in B3, then filter by date range, shift, operator or tool. Every statistic and all three plots recompute from the filtered rows only. Blank filter = include everything.
A10: 6 | B10: Recording readings by hand | C10: Data Collection Form is already set up to print: A4 landscape, one page, spec limits pulled from Settings. Ctrl+P.
A12: IF THE CHARTS LOOK EMPTY
B13: Press Ctrl+Alt+F9 | C13: That forces a full recalculation. The workbook is built to recalculate when it opens, but this settles it if a chart looks stale.
B14: Check Active = Y | C14: A feature with Active = N on Settings has no name in Data Entry row 4 and is excluded from Capability.
B15: Check the readings are numbers | C15: Values pasted as text are ignored by every statistic. Excel shows them left-aligned with a green corner marker.
B16: #N/A in the hidden columns is correct | C16: That is how the charts shrink and grow with the data - Excel skips #N/A points. Do not 'fix' those cells.
A18: CHART COLOUR KEY
B19: Blue line + markers | C19: Individual measurements
B20: Green dashed | C20: CL - the process mean
B21: Red | C21: UCL / LCL - 3-sigma control limits calculated from mR-bar
B22: Purple long-dash | C22: USL / LSL - your specification limits
B23: Histogram bars | C23: Distribution of all readings for that feature. The purple spikes mark the bins holding LSL and USL, so you can see the distribution against the tolerance rather than against itself.
A25: WHAT EACH SHEET IS FOR
B26: Settings | C26: Feature definitions and display / monitor options
B27: Data Entry | C27: All measurements. Column H onward
B28: Data Collection Form | C28: Printable sheet for recording readings off-PC
B29: Control Charts | C29: Per feature: stats panel, X chart, mR chart, histogram
B30: Monitor | C30: Live screen: 4 selectable slots + all-feature status table
B31: Visual SPC | C31: Filtered analysis and plots
B32: Capability | C32: Cp / Cpk / Pp / Ppk and verdicts
B33: Dashboard | C33: One-feature summary
B34: Document Control | C34: Doc ID, revision, owner
A36: DISPLAY OPTIONS (Settings, column F)
B37: F5 Chart Window | C37: How many of the most recent points the charts plot (default 200). Charts always follow the newest data.
B38: F6 Histogram Bins | C38: Number of histogram bars (default 15).
B39: F7 Show Spec Limits | C39: Y shows the USL/LSL lines, N hides them without deleting the limits.
A41: FOLDER MONITORING - THE ONLY PART THAT NEEDS MACROS
A42: 1 | B42: Save as .xlsm | C42: File > Save As > Excel Macro-Enabled Workbook. Macros cannot be stored in a .xlsx.
A43: 2 | B43: Import the module | C43: Alt+F11 > File > Import File > SPC_V13_Monitor.bas. (If you were sent the .txt version, rename it to .bas first, or paste its contents into a new module and drop the first Attribute line.)
A44: 3 | B44: Buttons appear | C44: Save, close and reopen the workbook. The buttons on the right of this sheet and on the Monitor sheet are created automatically. If they are missing, run SPC_BuildButtons once from Alt+F8.
A45: 4 | B45: Point it at a folder | C45: Settings F8 = folder to watch, F9 = pattern such as *.csv, F10 = seconds between scans, F11 = Y to move imported files into the archive subfolder named in F12.
A46: 5 | B46: Press Start Monitoring | C46: New files are appended to Data Entry, all charts refresh, and the Monitor sheet logs status, last scan, and files / rows imported. Each file is imported once - a hidden log prevents double counting.
...

Sheet Settings
A1: SPC CALCULATOR v13 - SETTINGS
A2: Yellow cells are yours to edit. Everything else is calculated.
A4: PARAMETER | B4: VALUE | C4: NOTES | E4: DISPLAY & MONITOR OPTIONS
A5: Number of Features | B5: 10 | C5: Features with full chart blocks (1-10). | E5: Chart Window (points) | F5: 200
A6: Data Rows Available | B6: 10000 | C6: Measurement rows on Data Entry. | E6: Histogram Bins | F6: 15
A7: Feature Start Column | B7: H | C7: First measurement column on Data Entry. | E7: Show Spec Limits | F7: Y
A8: Company | B8: R&G Precision Engineering Ltd | E8: Watch Folder
A9: Document ID | B9: RG-SPC-013 | E9: File Pattern | F9: *.csv
A10: Revision | B10: R01 | E10: Auto-Refresh (sec) | F10: 60
A11: Issue Date | B11: 2026-08-03 | E11: Archive Imported Files | F11: Y
A12: Owner | B12: Andrij Medwid, Senior Quality Engineer | E12: Archive Subfolder | F12: archive
A13: Status | B13: DRAFT | C13: DRAFT / ISSUED / SUPERSEDED | E13: Kiosk Cycle (sec) | F13: 20
E14: Charts plot the most recent 'Chart Window' points.
A15: FEATURE DEFINITIONS
A16: # | B16: Feature Name | C16: Nominal | D16: LSL | E16: USL | F16: Unit | G16: Active
A17: 1 | B17: Feature 1 | C17: 25 | D17: 24.76 | E17: 25.24 | F17: mm | G17: Y
A18: 2 | B18: Feature 2 | C18: 12.5 | D18: 12.22 | E18: 12.78 | F18: mm | G18: Y
A19: 3 | B19: Feature 3 | C19: 8 | D19: 7.8 | E19: 8.2 | F19: mm | G19: Y
A20: 4 | B20: Feature 4 | C20: 50 | D20: 49.2 | E20: 50.8 | F20: mm | G20: Y
A21: 5 | B21: Feature 5 | C21: 3.17 | D21: 3.122 | E21: 3.218 | F21: mm | G21: Y
A22: 6 | B22: Feature 6 | C22: 6.32 | D22: 6.208 | E22: 6.432 | F22: mm | G22: Y
A23: 7 | B23: Feature 7 | C23: 10.02 | D23: 9.94 | E23: 10.1 | F23: mm | G23: Y
A24: 8 | B24: Feature 8 | C24: 15 | D24: 14.72 | E24: 15.28 | F24: mm | G24: Y
A25: 9 | B25: Feature 9 | C25: 20 | D25: 19.76 | E25: 20.24 | F25: mm | G25: Y
A26: 10 | B26: Feature 10 | C26: 30 | D26: 29.56 | E26: 30.44 | F26: mm | G26: Y
A27: 11 | B27: Feature 11 | F27: mm | G27: N
A28: 12 | B28: Feature 12 | F28: mm | G28: N
A29: 13 | B29: Feature 13 | F29: mm | G29: N
A30: 14 | B30: Feature 14 | F30: mm | G30: N
A31: 15 | B31: Feature 15 | F31: mm | G31: N
A32: 16 | B32: Feature 16 | F32: mm | G32: N
A33: 17 | B33: Feature 17 | F33: mm | G33: N
A34: 18 | B34: Feature 18 | F34: mm | G34: N
A35: 19 | B35: Feature 19 | F35: mm | G35: N
A36: 20 | B36: Feature 20 | F36: mm | G36: N
A37: 21 | B37: Feature 21 | F37: mm | G37: N
A38: 22 | B38: Feature 22 | F38: mm | G38: N
... A66: 50 | B66: Feature 50 | F66: mm | G66: N

Sheet Data Entry
A1: SPC CALCULATOR v13 - DATA ENTRY
A2: Type measurements from column H onward. Every chart in the workbook follows this sheet.
A4: Sample # | B4: Subgroup | C4: Date | D4: Shift | E4: Operator | F4: Tool ID | G4: Cluster | H4: =IF(Settings!G17="Y",Settings!B17,"") | I4: =IF(Settings!G18="Y",Settings!B18,"") | J4: =IF(Settings!G19="Y",Settings!B19,"") | K4: =IF(Settings!G20="Y",Settings!B20,"") | L4: =IF(Settings!G21="Y",Settings!B21,"") | M4: =IF(Settings!G22="Y",Settings!B22,"") | N4: =IF(Settings!G23="Y",Settings!B23,"") | O4: =IF(Settings!G24="Y",Settings!B24,"") | P4: =IF(Settings!G25="Y",Settings!B25,"") | Q4: =IF(Settings!G26="Y",Settings!B26,"") | R4: =IF(Settings!G27="Y",Settings!B27,"") | S4: =IF(Settings!G28="Y",Settings!B28,"") | T4: =IF(Settings!G29="Y",Settings!B29,"") | U4: =IF(Settings!G30="Y",Settings!B30,"") | V4: =IF(Settings!G31="Y",Settings!B31,"") | W4: =IF(Settings!G32="Y",Settings!B32,"") | X4: =IF(Settings!G33="Y",Settings!B33,"") | Y4: =IF(Settings!G34="Y",Settings!B34,"") | Z4: =IF(Settings!G35="Y",Settings!B35,"") | AA4: =IF(Settings!G36="Y",Settings!B36,"") | AB4: =IF(Settings!G37="Y",Settings!B37,"") | AC4: =IF(Settings!G38="Y",Settings!B38,"") | AD4: =IF(Settings!G39="Y",Settings!B39,"") | AE4: =IF(Settings!G40="Y",Settings!B40,"") | AF4: =IF(Settings!G41="Y",Settings!B41,"") | AG4: =IF(Settings!G42="Y",Settings!B42,"") | AH4: =IF(Settings!G43="Y",Settings!B43,"") | AI4: =IF(Settings!G44="Y",Settings!B44,"") | AJ4: =IF(Settings!G45="Y",Settings!B45,"") | AK4: =IF(Settings!G46="Y",Settings!B46,"") | AL4: =IF(Settings!G47="Y",Settings!B47,"") | AM4: =IF(Settings!G48="Y",Settings!B48,"") | AN4: =IF(Settings!G49="Y",Settings!B49,"") | AO4: =IF(Settings!G50="Y",Settings!B50,"") | AP4: =IF(Settings!G51="Y",Settings!B51,"") | AQ4: =IF(Settings!G52="Y",Settings!B52,"") | AR4: =IF(Settings!G53="Y",Settings!B53,"") | AS4: =IF(Settings!G54="Y",Settings!B54,"") | AT4: =IF(Settings!G55="Y",Settings!B55,"") | AU4: =IF(Settings!G56="Y",Settings!B56,"") | AV4: =IF(Settings!G57="Y",Settings!B57,"") | AW4: =IF(Settings!G58="Y",Settings!B58,"") | AX4: =IF(Settings!G59="Y",Settings!B59,"") | AY4: =IF(Settings!G60="Y",Settings!B60,"") | AZ4: =IF(Settings!G61="Y",Settings!B61,"") | BA4: =IF(Settings!G62="Y",Settings!B62,"") | BB4: =IF(Settings!G63="Y",Settings!B63,"") | BC4: =IF(Settings!G64="Y",Settings!B64,"") | BD4: =IF(Settings!G65="Y",Settings!B65,"") | BE4: =IF(Settings!G66="Y",Settings!B66,"")
A5: =IF(H5="","",ROW()-4) | B5: =IF(H5="","",ROW()-4) | C5: 2026-07-02 | D5: A | E5: OP1 | F5: T01 | H5: 25.0299 | I5: 12.4614 | J5: 7.9877 | K5: 49.9469 | L5: 3.1644 | M5: 6.3588 | N5: 10.0064 | O5: 14.9009 | P5: 20.0588 | Q5: 29.8416
A6: =IF(H6="","",ROW()-4) | B6: =IF(H6="","",ROW()-4) | C6: 2026-07-03 | D6: B | E6: OP2 | F6: T02 | H6: 25.0135 | I6: 12.5357 | J6: 8.0434 | K6: 49.8052 | L6: 3.1484 | M6: 6.2908 | N6: 10.065 | O6: 14.9886 | P6: 20.087 | Q6: 29.9475
A7: =IF(H7="","",ROW()-4) | B7: =IF(H7="","",ROW()-4) | C7: 2026-07-04 | D7: C | E7: OP3 | F7: T03 | H7: 25.0489 | I7: 12.5464 | J7: 7.8927 | K7: 49.9122 | L7: 3.1711 | M7: 6.2807 | N7: 10.0633 | O7: 15.0748 | P7: 20.0639 | Q7: 29.9953
A8: =IF(H8="","",ROW()-4) | B8: =IF(H8="","",ROW()-4) | C8: 2026-07-05 | D8: A | E8: OP1 | F8: T01 | H8: 24.9139 | I8: 12.4755 | J8: 8.0409 | K8: 50.2694 | L8: 3.1664 | M8: 6.3147 | N8: 9.9929 | O8: 14.9534 | P8: 20.0371 | Q8: 29.9516
A9: =IF(H9="","",ROW()-4) | B9: =IF(H9="","",ROW()-4) | C9: 2026-07-06 | D9: B | E9: OP2 | F9: T02 | H9: 25.0293 | I9: 12.5171 | J9: 7.9491 | K9: 50.0077 | L9: 3.1722 | M9: 6.2928 | N9: 9.9834 | O9: 14.9605 | P9: 20.0318 | Q9: 29.6496
A10: =IF(H10="","",ROW()-4) | B10: =IF(H10="","",ROW()-4) | C10: 2026-07-07 | D10: C | E10: OP3 | F10: T03 | H10: 25.021 | I10: 12.4868 | J10: 7.9857 | K10: 50.1995 | L10: 3.1746 | M10: 6.3208 | N10: 9.9887 | O10: 15.0139 | P10: 19.9802 | Q10: 29.9917
A11: =IF(H11="","",ROW()-4) | B11: =IF(H11="","",ROW()-4) | C11: 2026-07-08 | D11: A | E11: OP1 | F11: T01 | H11: 25.0503 | I11: 12.5301 | J11: 7.9254 | K11: 50.3024 | L11: 3.1616 | M11: 6.2626 | N11: 10.0151 | O11: 14.971 | P11: 20.0391 | Q11: 29.9619
A12: =IF(H12="","",ROW()-4) | B12: =IF(H12="","",ROW()-4) | C12: 2026-07-09 | D12: B | E12: OP2 | F12: T02 | H12: 25.0967 | I12: 12.5871 | J12: 7.9636 | K12: 49.7933 | L12: 3.165 | M12: 6.3185 | N12: 10.0085 | O12: 15.0481 | P12: 19.9618 | Q12: 29.953
A13: =IF(H13="","",ROW()-4) | B13: =IF(H13="","",ROW()-4) | C13: 2026-07-10 | D13: C | E13: OP3 | F13: T03 | H13: 24.9403 | I13: 12.4637 | J13: 8.0343 | K13: 50.3662 | L13: 3.1678 | M13: 6.2868 | N13: 10.0084 | O13: 15.0646 | P13: 20.0031 | Q13: 29.9903
A14: =IF(H14="","",ROW()-4) | B14: =IF(H14="","",ROW()-4) | C14: 2026-07-11 | D14: A | E14: OP1 | F14: T01 | H14: 24.8808 | I14: 12.4055 | J14: 8.0498 | K14: 49.8887 | L14: 3.1726 | M14: 6.3258 | N14: 10.0436 | O14: 14.9974 | P14: 19.9681 | Q14: 30.0016
A15: =IF(H15="","",ROW()-4) | B15: =IF(H15="","",ROW()-4) | C15: 2026-07-12 | D15: B | E15: OP2 | F15: T02 | H15: 24.9368 | I15: 12.509 | J15: 7.976 | K15: 50.0298 | L15: 3.1661 | M15: 6.301 | N15: 10.0034 | O15: 14.9439 | P15: 19.9605 | Q15: 29.9558
A16: =IF(H16="","",ROW()-4) | B16: =IF(H16="","",ROW()-4) | C16: 2026-07-13 | D16: C | E16: OP3 | F16: T03 | H16: 25.1267 | I16: 12.4524 | J16: 8.0194 | K16: 50.2784 | L16: 3.184 | M16: 6.3026 | N16: 10.0199 | O16: 15.0645 | P16: 19.9884 | Q16: 29.7797
... A104: =IF(H104="","",ROW()-4) | B104: =IF(H104="","",ROW()-4) | C104: 2026-10-09 | D104: A | E104: OP1 | F104: T01 | H104: 25.1055 | I104: 12.6182 | J104: 8.0411 | K104: 49.7901 | L104: 3.1822 | M104: 6.3063 | N104: 10.0007 | O104: 14.8232 | P104: 19.9699 | Q104: 29.9563
A105: =IF(H105="","",ROW()-4) | B105: =IF(H105="","",ROW()-4)
A106: =IF(H106="","",ROW()-4) | B106: =IF(H106="","",ROW()-4)
A107: =IF(H107="","",ROW()-4) | B107: =IF(H107="","",ROW()-4)
A108: =IF(H108="","",ROW()-4) | B108: =IF(H108="","",ROW()-4)
A109: =IF(H109="","",ROW()-4) | B109: =IF(H109="","",ROW()-4)
A110: =IF(H110="","",ROW()-4) | B110: =IF(H110="","",ROW()-4)
A111: =IF(H111="","",ROW()-4) | B111: =IF(H111="","",ROW()-4)
A112: =IF(H112="","",ROW()-4) | B112: =IF(H112="","",ROW()-4)
A113: =IF(H113="","",ROW()-4) | B113: =IF(H113="","",ROW()-4)
A114: =IF(H114="","",ROW()-4) | B114: =IF(H114="","",ROW()-4)
A115: =IF(H115="","",ROW()-4) | B115: =IF(H115="","",ROW()-4)
A116: =IF(H116="","",ROW()-4) | B116: =IF(H116="","",ROW()-4)
... A10004: =IF(H10004="","",ROW()-4) | B10004: =IF(H10004="","",ROW()-4)
A10007: STATISTICS (auto-calculated)
A10008: Statistic | H10008: =H4 | I10008: =I4 | J10008: =J4 | K10008: =K4 | L10008: =L4 | M10008: =M4 | N10008: =N4 | O10008: =O4 | ... BE10008: =BE4
A10009: Count (n) | H10009: =COUNT('Data Entry'!$H$5:$H$10004) | I10009: =COUNT('Data Entry'!$I$5:$I$10004) | J10009: =COUNT('Data Entry'!$J$5:$J$10004) | K10009: =COUNT('Data Entry'!$K$5:$K$10004) | L10009: =COUNT('Data Entry'!$L$5:$L$10004) | M10009: =COUNT('Data Entry'!$M$5:$M$10004) | N10009: =COUNT('Data Entry'!$N$5:$N$10004) | O10009: =COUNT('Data Entry'!$O$5:$O$10004) | P10009: =COUNT('Data Entry'!$P$5:$P$10004) | Q10009: =COUNT('Data Entry'!$Q$5:$Q$10004) | R10009: =COUNT('Data Entry'!$R$5:$R$10004) | S10009: =COUNT('Data Entry'!$S$5:$S$10004) | T10009: =COUNT('Data Entry'!$T$5:$T$10004) | U10009: =COUNT('Data Entry'!$U$5:$U$10004) | V10009: =COUNT('Data Entry'!$V$5:$V$10004) | W10009: =COUNT('Data Entry'!$W$5:$W$10004) | X10009: =COUNT('Data Entry'!$X$5:$X$10004) | Y10009: =COUNT('Data Entry'!$Y$5:$Y$10004) | Z10009: =COUNT('Data Entry'!$Z$5:$Z$10004) | AA10009: =COUNT('Data Entry'!$AA$5:$AA$10004) | AB10009: =COUNT('Data Entry'!$AB$5:$AB$10004) | AC10009: =COUNT('Data Entry'!$AC$5:$AC$10004) | AD10009: =COUNT('Data Entry'!$AD$5:$AD$10004) | AE10009: =COUNT('Data Entry'!$AE$5:$AE$10004) | AF10009: =COUNT('Data Entry'!$AF$5:$AF$10004) | AG10009: =COUNT('Data Entry'!$AG$5:$AG$10004) | AH10009: =COUNT('Data Entry'!$AH$5:$AH$10004) | AI10009: =COUNT('Data Entry'!$AI$5:$AI$10004) | AJ10009: =COUNT('Data Entry'!$AJ$5:$AJ$10004) | AK10009: =COUNT('Data Entry'!$AK$5:$AK$10004) | AL10009: =COUNT('Data Entry'!$AL$5:$AL$10004) | AM10009: =COUNT('Data Entry'!$AM$5:$AM$10004) | AN10009: =COUNT('Data Entry'!$AN$5:$AN$10004) | AO10009: =COUNT('Data Entry'!$AO$5:$AO$10004) | AP10009: =COUNT('Data Entry'!$AP$5:$AP$10004) | AQ10009: =COUNT('Data Entry'!$AQ$5:$AQ$10004) | AR10009: =COUNT('Data Entry'!$AR$5:$AR$10004) | AS10009: =COUNT('Data Entry'!$AS$5:$AS$10004) | AT10009: =COUNT('Data Entry'!$AT$5:$AT$10004) | AU10009: =COUNT('Data Entry'!$AU$5:$AU$10004) | AV10009: =COUNT('Data Entry'!$AV$5:$AV$10004) | AW10009: =COUNT('Data Entry'!$AW$5:$AW$10004) | AX10009: =COUNT('Data Entry'!$AX$5:$AX$10004) | AY10009: =COUNT('Data Entry'!$AY$5:$AY$10004) | AZ10009: =COUNT('Data Entry'!$AZ$5:$AZ$10004) | BA10009: =COUNT('Data Entry'!$BA$5:$BA$10004) | BB10009: =COUNT('Data Entry'!$BB$5:$BB$10004) | BC10009: =COUNT('Data Entry'!$BC$5:$BC$10004) | BD10009: =COUNT('Data Entry'!$BD$5:$BD$10004) | BE10009: =COUNT('Data Entry'!$BE$5:$BE$10004)
A10010: Mean (X-bar) | H10010: =IF(COUNT('Data Entry'!$H$5:$H$10004)=0,"",AVERAGE('Data Entry'!$H$5:$H$10004)) | I10010: =IF(COUNT('Data Entry'!$I$5:$I$10004)=0,"",AVERAGE('Data Entry'!$I$5:$I$10004)) | J10010: =IF(COUNT('Data Entry'!$J$5:$J$10004)=0,"",AVERAGE('Data Entry'!$J$5:$J$10004)) | K10010: =IF(COUNT('Data Entry'!$K$5:$K$10004)=0,"",AVERAGE('Data Entry'!$K$5:$K$10004)) | L10010: =IF(COUNT('Data Entry'!$L$5:$L$10004)=0,"",AVERAGE('Data Entry'!$L$5:$L$10004)) | M10010: =IF(COUNT('Data Entry'!$M$5:$M$10004)=0,"",AVERAGE('Data Entry'!$M$5:$M$10004)) | N10010: =IF(COUNT('Data Entry'!$N$5:$N$10004)=0,"",AVERAGE('Data Entry'!$N$5:$N$10004)) | O10010: =IF(COUNT('Data Entry'!$O$5:$O$10004)=0,"",AVERAGE('Data Entry'!$O$5:$O$10004)) | P10010: =IF(COUNT('Data Entry'!$P$5:$P$10004)=0,"",AVERAGE('Data Entry'!$P$5:$P$10004)) | Q10010: =IF(COUNT('Data Entry'!$Q$5:$Q$10004)=0,"",AVERAGE('Data Entry'!$Q$5:$Q$10004)) | R10010: =IF(COUNT('Data Entry'!$R$5:$R$10004)=0,"",AVERAGE('Data Entry'!$R$5:$R$10004)) | S10010: =IF(COUNT('Data Entry'!$S$5:$S$10004)=0,"",AVERAGE('Data Entry'!$S$5:$S$10004)) | T10010: =IF(COUNT('Data Entry'!$T$5:$T$10004)=0,"",AVERAGE('Data Entry'!$T$5:$T$10004)) | U10010: =IF(COUNT('Data Entry'!$U$5:$U$10004)=0,"",AVERAGE('Data Entry'!$U$5:$U$10004)) | V10010: =IF(COUNT('Data Entry'!$V$5:$V$10004)=0,"",AVERAGE('Data Entry'!$V$5:$V$10004)) | W10010: =IF(COUNT('Data Entry'!$W$5:$W$10004)=0,"",AVERAGE('Data Entry'!$W$5:$W$10004)) | X10010: =IF(COUNT('Data Entry'!$X$5:$X$10004)=0,"",AVERAGE('Data Entry'!$X$5:$X$10004)) | Y10010: =IF(COUNT('Data Entry'!$Y$5:$Y$10004)=0,"",AVERAGE('Data Entry'!$Y$5:$Y$10004)) | Z10010: =IF(COUNT('Data Entry'!$Z$5:$Z$10004)=0,"",AVERAGE('Data Entry'!$Z$5:$Z$10004)) | AA10010: =IF(COUNT('Data Entry'!$AA$5:$AA$10004)=0,"",AVERAGE('Data Entry'!$AA$5:$AA$10004)) | AB10010: =IF(COUNT('Data Entry'!$AB$5:$AB$10004)=0,"",AVERAGE('Data Entry'!$AB$5:$AB$10004)) | AC10010: =IF(COUNT('Data Entry'!$AC$5:$AC$10004)=0,"",AVERAGE('Data Entry'!$AC$5:$AC$10004)) | AD10010: =IF(COUNT('Data Entry'!$AD$5:$AD$10004)=0,"",AVERAGE('Data Entry'!$AD$5:$AD$10004)) | AE10010: =IF(COUNT('Data Entry'!$AE$5:$AE$10004)=0,"",AVERAGE('Data Entry'!$AE$5:$AE$10004)) | AF10010: =IF(COUNT('Data Entry'!$AF$5:$AF$10004)=0,"",AVERAGE('Data Entry'!$AF$5:$AF$10004)) | AG10010: =IF(COUNT('Data Entry'!$AG$5:$AG$10004)=0,"",AVERAGE('Data Entry'!$AG$5:$AG$10004)) | AH10010: =IF(COUNT('Data Entry'!$AH$5:$AH$10004)=0,"",AVERAGE('Data Entry'!$AH$5:$AH$10004)) | AI10010: =IF(COUNT('Data Entry'!$AI$5:$AI$10004)=0,"",AVERAGE('Data Entry'!$AI$5:$AI$10004)) | AJ10010: =IF(COUNT('Data Entry'!$AJ$5:$AJ$10004)=0,"",AVERAGE('Data Entry'!$AJ$5:$AJ$10004)) | AK10010: =IF(COUNT('Data Entry'!$AK$5:$AK$10004)=0,"",AVERAGE('Data Entry'!$AK$5:$AK$10004)) | AL10010: =IF(COUNT('Data Entry'!$AL$5:$AL$10004)=0,"",AVERAGE('Data Entry'!$AL$5:$AL$10004)) | AM10010: =IF(COUNT('Data Entry'!$AM$5:$AM$10004)=0,"",AVERAGE('Data Entry'!$AM$5:$AM$10004)) | AN10010: =IF(COUNT('Data Entry'!$AN$5:$AN$10004)=0,"",AVERAGE('Data Entry'!$AN$5:$AN$10004)) | AO10010: =IF(COUNT('Data Entry'!$AO$5:$AO$10004)=0,"",AVERAGE('Data Entry'!$AO$5:$AO$10004)) | AP10010: =IF(COUNT('Data Entry'!$AP$5:$AP$10004)=0,"",AVERAGE('Data Entry'!$AP$5:$AP$10004)) | AQ10010: =IF(COUNT('Data Entry'!$AQ$5:$AQ$10004)=0,"",AVERAGE('Data Entry'!$AQ$5:$AQ$10004)) | AR10010: =IF(COUNT('Data Entry'!$AR$5:$AR$10004)=0,"",AVERAGE('Data Entry'!$AR$5:$AR$10004)) | AS10010: =IF(COUNT('Data Entry'!$AS$5:$AS$10004)=0,"",AVERAGE('Data Entry'!$AS$5:$AS$10004)) | AT10010: =IF(COUNT('Data Entry'!$AT$5:$AT$10004)=0,"",AVERAGE('Data Entry'!$AT$5:$AT$10004)) | AU10010: =IF(COUNT('Data Entry'!$AU$5:$AU$10004)=0,"",AVERAGE('Data Entry'!$AU$5:$AU$10004)) | AV10010: =IF(COUNT('Data Entry'!$AV$5:$AV$10004)=0,"",AVERAGE('Data Entry'!$AV$5:$AV$10004)) | AW10010: =IF(COUNT('Data Entry'!$AW$5:$AW$10004)=0,"",AVERAGE('Data Entry'!$AW$5:$AW$10004)) | AX10010: =IF(COUNT('Data Entry'!$AX$5:$AX$10004)=0,"",AVERAGE('Data Entry'!$AX$5:$AX$10004)) | AY10010: =IF(COUNT('Data Entry'!$AY$5:$AY$10004)=0,"",AVERAGE('Data Entry'!$AY$5:$AY$10004)) | AZ10010: =IF(COUNT('Data Entry'!$AZ$5:$AZ$10004)=0,"",AVERAGE('Data Entry'!$AZ$5:$AZ$10004)) | BA10010: =IF(COUNT('Data Entry'!$BA$5:$BA$10004)=0,"",AVERAGE('Data Entry'!$BA$5:$BA$10004)) | BB10010: =IF(COUNT('Data Entry'!$BB$5:$BB$10004)=0,"",AVERAGE('Data Entry'!$BB$5:$BB$10004)) | BC10010: =IF(COUNT('Data Entry'!$BC$5:$BC$10004)=0,"",AVERAGE('Data Entry'!$BC$5:$BC$10004)) | BD10010: =IF(COUNT('Data Entry'!$BD$5:$BD$10004)=0,"",AVERAGE('Data Entry'!$BD$5:$BD$10004)) | BE10010: =IF(COUNT('Data Entry'!$BE$5:$BE$10004)=0,"",AVERAGE('Data Entry'!$BE$5:$BE$10004))
A10011: Min | H10011: =IF(COUNT('Data Entry'!$H$5:$H$10004)=0,"",MIN('Data Entry'!$H$5:$H$10004)) | I10011: =IF(COUNT('Data Entry'!$I$5:$I$10004)=0,"",MIN('Data Entry'!$I$5:$I$10004)) | J10011: =IF(COUNT('Data Entry'!$J$5:$J$10004)=0,"",MIN('Data Entry'!$J$5:$J$10004)) | K10011: =IF(COUNT('Data Entry'!$K$5:$K$10004)=0,"",MIN('Data Entry'!$K$5:$K$10004)) | L10011: =IF(COUNT('Data Entry'!$L$5:$L$10004)=0,"",MIN('Data Entry'!$L$5:$L$10004)) | M10011: =IF(COUNT('Data Entry'!$M$5:$M$10004)=0,"",MIN('Data Entry'!$M$5:$M$10004)) | N10011: =IF(COUNT('Data Entry'!$N$5:$N$10004)=0,"",MIN('Data Entry'!$N$5:$N$10004)) | O10011: =IF(COUNT('Data Entry'!$O$5:$O$10004)=0,"",MIN('Data Entry'!$O$5:$O$10004)) | P10011: =IF(COUNT('Data Entry'!$P$5:$P$10004)=0,"",MIN('Data Entry'!$P$5:$P$10004)) | Q10011: =IF(COUNT('Data Entry'!$Q$5:$Q$10004)=0,"",MIN('Data Entry'!$Q$5:$Q$10004)) | R10011: =IF(COUNT('Data Entry'!$R$5:$R$10004)=0,"",MIN('Data Entry'!$R$5:$R$10004)) | S10011: =IF(COUNT('Data Entry'!$S$5:$S$10004)=0,"",MIN('Data Entry'!$S$5:$S$10004)) | T10011: =IF(COUNT('Data Entry'!$T$5:$T$10004)=0,"",MIN('Data Entry'!$T$5:$T$10004)) | U10011: =IF(COUNT('Data Entry'!$U$5:$U$10004)=0,"",MIN('Data Entry'!$U$5:$U$10004)) | V10011: =IF(COUNT('Data Entry'!$V$5:$V$10004)=0,"",MIN('Data Entry'!$V$5:$V$10004)) | W10011: =IF(COUNT('Data Entry'!$W$5:$W$10004)=0,"",MIN('Data Entry'!$W$5:$W$10004)) | X10011: =IF(COUNT('Data Entry'!$X$5:$X$10004)=0,"",MIN('Data Entry'!$X$5:$X$10004)) | Y10011: =IF(COUNT('Data Entry'!$Y$5:$Y$10004)=0,"",MIN('Data Entry'!$Y$5:$Y$10004)) | Z10011: =IF(COUNT('Data Entry'!$Z$5:$Z$10004)=0,"",MIN('Data Entry'!$Z$5:$Z$10004)) | AA10011: =IF(COUNT('Data Entry'!$AA$5:$AA$10004)=0,"",MIN('Data Entry'!$AA$5:$AA$10004)) | AB10011: =IF(COUNT('Data Entry'!$AB$5:$AB$10004)=0,"",MIN('Data Entry'!$AB$5:$AB$10004)) | AC10011: =IF(COUNT('Data Entry'!$AC$5:$AC$10004)=0,"",MIN('Data Entry'!$AC$5:$AC$10004)) | AD10011: =IF(COUNT('Data Entry'!$AD$5:$AD$10004)=0,"",MIN('Data Entry'!$AD$5:$AD$10004)) | AE10011: =IF(COUNT('Data Entry'!$AE$5:$AE$10004)=0,"",MIN('Data Entry'!$AE$5:$AE$10004)) | AF10011: =IF(COUNT('Data Entry'!$AF$5:$AF$10004)=0,"",MIN('Data Entry'!$AF$5:$AF$10004)) | AG10011: =IF(COUNT('Data Entry'!$AG$5:$AG$10004)=0,"",MIN('Data Entry'!$AG$5:$AG$10004)) | AH10011: =IF(COUNT('Data Entry'!$AH$5:$AH$10004)=0,"",MIN('Data Entry'!$AH$5:$AH$10004)) | AI10011: =IF(COUNT('Data Entry'!$AI$5:$AI$10004)=0,"",MIN('Data Entry'!$AI$5:$AI$10004)) | AJ10011: =IF(COUNT('Data Entry'!$AJ$5:$AJ$10004)=0,"",MIN('Data Entry'!$AJ$5:$AJ$10004)) | AK10011: =IF(COUNT('Data Entry'!$AK$5:$AK$10004)=0,"",MIN('Data Entry'!$AK$5:$AK$10004)) | AL10011: =IF(COUNT('Data Entry'!$AL$5:$AL$10004)=0,"",MIN('Data Entry'!$AL$5:$AL$10004)) | AM10011: =IF(COUNT('Data Entry'!$AM$5:$AM$10004)=0,"",MIN('Data Entry'!$AM$5:$AM$10004)) | AN10011: =IF(COUNT('Data Entry'!$AN$5:$AN$10004)=0,"",MIN('Data Entry'!$AN$5:$AN$10004)) | AO10011: =IF(COUNT('Data Entry'!$AO$5:$AO$10004)=0,"",MIN('Data Entry'!$AO$5:$AO$10004)) | AP10011: =IF(COUNT('Data Entry'!$AP$5:$AP$10004)=0,"",MIN('Data Entry'!$AP$5:$AP$10004)) | AQ10011: =IF(COUNT('Data Entry'!$AQ$5:$AQ$10004)=0,"",MIN('Data Entry'!$AQ$5:$AQ$10004)) | AR10011: =IF(COUNT('Data Entry'!$AR$5:$AR$10004)=0,"",MIN('Data Entry'!$AR$5:$AR$10004)) | AS10011: =IF(COUNT('Data Entry'!$AS$5:$AS$10004)=0,"",MIN('Data Entry'!$AS$5:$AS$10004)) | AT10011: =IF(COUNT('Data Entry'!$AT$5:$AT$10004)=0,"",MIN('Data Entry'!$AT$5:$AT$10004)) | AU10011: =IF(COUNT('Data Entry'!$AU$5:$AU$10004)=0,"",MIN('Data Entry'!$AU$5:$AU$10004)) | AV10011: =IF(COUNT('Data Entry'!$AV$5:$AV$10004)=0,"",MIN('Data Entry'!$AV$5:$AV$10004)) | AW10011: =IF(COUNT('Data Entry'!$AW$5:$AW$10004)=0,"",MIN('Data Entry'!$AW$5:$AW$10004)) | AX10011: =IF(COUNT('Data Entry'!$AX$5:$AX$10004)=0,"",MIN('Data Entry'!$AX$5:$AX$10004)) | AY10011: =IF(COUNT('Data Entry'!$AY$5:$AY$10004)=0,"",MIN('Data Entry'!$AY$5:$AY$10004)) | AZ10011: =IF(COUNT('Data Entry'!$AZ$5:$AZ$10004)=0,"",MIN('Data Entry'!$AZ$5:$AZ$10004)) | BA10011: =IF(COUNT('Data Entry'!$BA$5:$BA$10004)=0,"",MIN('Data Entry'!$BA$5:$BA$10004)) | BB10011: =IF(COUNT('Data Entry'!$BB$5:$BB$10004)=0,"",MIN('Data Entry'!$BB$5:$BB$10004)) | BC10011: =IF(COUNT('Data Entry'!$BC$5:$BC$10004)=0,"",MIN('Data Entry'!$BC$5:$BC$10004)) | BD10011: =IF(COUNT('Data Entry'!$BD$5:$BD$10004)=0,"",MIN('Data Entry'!$BD$5:$BD$10004)) | BE10011: =IF(COUNT('Data Entry'!$BE$5:$BE$10004)=0,"",MIN('Data Entry'!$BE$5:$BE$10004))
A10012: Max | H10012: =IF(COUNT('Data Entry'!$H$5:$H$10004)=0,"",MAX('Data Entry'!$H$5:$H$10004)) | I10012: =IF(COUNT('Data Entry'!$I$5:$I$10004)=0,"",MAX('Data Entry'!$I$5:$I$10004)) | J10012: =IF(COUNT('Data Entry'!$J$5:$J$10004)=0,"",MAX('Data Entry'!$J$5:$J$10004)) | K10012: =IF(COUNT('Data Entry'!$K$5:$K$10004)=0,"",MAX('Data Entry'!$K$5:$K$10004)) | L10012: =IF(COUNT('Data Entry'!$L$5:$L$10004)=0,"",MAX('Data Entry'!$L$5:$L$10004)) | M10012: =IF(COUNT('Data Entry'!$M$5:$M$10004)=0,"",MAX('Data Entry'!$M$5:$M$10004)) | N10012: =IF(COUNT('Data Entry'!$N$5:$N$10004)=0,"",MAX('Data Entry'!$N$5:$N$10004)) | O10012: =IF(COUNT('Data Entry'!$O$5:$O$10004)=0,"",MAX('Data Entry'!$O$5:$O$10004)) | P10012: =IF(COUNT('Data Entry'!$P$5:$P$10004)=0,"",MAX('Data Entry'!$P$5:$P$10004)) | Q10012: =IF(COUNT('Data Entry'!$Q$5:$Q$10004)=0,"",MAX('Data Entry'!$Q$5:$Q$10004)) | R10012: =IF(COUNT('Data Entry'!$R$5:$R$10004)=0,"",MAX('Data Entry'!$R$5:$R$10004)) | S10012: =IF(COUNT('Data Entry'!$S$5:$S$10004)=0,"",MAX('Data Entry'!$S$5:$S$10004)) | T10012: =IF(COUNT('Data Entry'!$T$5:$T$10004)=0,"",MAX('Data Entry'!$T$5:$T$10004)) | U10012: =IF(COUNT('Data Entry'!$U$5:$U$10004)=0,"",MAX('Data Entry'!$U$5:$U$10004)) | V10012: =IF(COUNT('Data Entry'!$V$5:$V$10004)=0,"",MAX('Data Entry'!$V$5:$V$10004)) | W10012: =IF(COUNT('Data Entry'!$W$5:$W$10004)=0,"",MAX('Data Entry'!$W$5:$W$10004)) | X10012: =IF(COUNT('Data Entry'!$X$5:$X$10004)=0,"",MAX('Data Entry'!$X$5:$X$10004)) | Y10012: =IF(COUNT('Data Entry'!$Y$5:$Y$10004)=0,"",MAX('Data Entry'!$Y$5:$Y$10004)) | Z10012: =IF(COUNT('Data Entry'!$Z$5:$Z$10004)=0,"",MAX('Data Entry'!$Z$5:$Z$10004)) | AA10012: =IF(COUNT('Data Entry'!$AA$5:$AA$10004)=0,"",MAX('Data Entry'!$AA$5:$AA$10004)) | AB10012: =IF(COUNT('Data Entry'!$AB$5:$AB$10004)=0,"",MAX('Data Entry'!$AB$5:$AB$10004)) | AC10012: =IF(COUNT('Data Entry'!$AC$5:$AC$10004)=0,"",MAX('Data Entry'!$AC$5:$AC$10004)) | AD10012: =IF(COUNT('Data Entry'!$AD$5:$AD$10004)=0,"",MAX('Data Entry'!$AD$5:$AD$10004)) | AE10012: =IF(COUNT('Data Entry'!$AE$5:$AE$10004)=0,"",MAX('Data Entry'!$AE$5:$AE$10004)) | AF10012: =IF(COUNT('Data Entry'!$AF$5:$AF$10004)=0,"",MAX('Data Entry'!$AF$5:$AF$10004)) | AG10012: =IF(COUNT('Data Entry'!$AG$5:$AG$10004)=0,"",MAX('Data Entry'!$AG$5:$AG$10004)) | AH10012: =IF(COUNT('Data Entry'!$AH$5:$AH$10004)=0,"",MAX('Data Entry'!$AH$5:$AH$10004)) | AI10012: =IF(COUNT('Data Entry'!$AI$5:$AI$10004)=0,"",MAX('Data Entry'!$AI$5:$AI$10004)) | AJ10012: =IF(COUNT('Data Entry'!$AJ$5:$AJ$10004)=0,"",MAX('Data Entry'!$AJ$5:$AJ$10004)) | AK10012: =IF(COUNT('Data Entry'!$AK$5:$AK$10004)=0,"",MAX('Data Entry'!$AK$5:$AK$10004)) | AL10012: =IF(COUNT('Data Entry'!$AL$5:$AL$10004)=0,"",MAX('Data Entry'!$AL$5:$AL$10004)) | AM10012: =IF(COUNT('Data Entry'!$AM$5:$AM$10004)=0,"",MAX('Data Entry'!$AM$5:$AM$10004)) | AN10012: =IF(COUNT('Data Entry'!$AN$5:$AN$10004)=0,"",MAX('Data Entry'!$AN$5:$AN$10004)) | AO10012: =IF(COUNT('Data Entry'!$AO$5:$AO$10004)=0,"",MAX('Data Entry'!$AO$5:$AO$10004)) | AP10012: =IF(COUNT('Data Entry'!$AP$5:$AP$10004)=0,"",MAX('Data Entry'!$AP$5:$AP$10004)) | AQ10012: =IF(COUNT('Data Entry'!$AQ$5:$AQ$10004)=0,"",MAX('Data Entry'!$AQ$5:$AQ$10004)) | AR10012: =IF(COUNT('Data Entry'!$AR$5:$AR$10004)=0,"",MAX('Data Entry'!$AR$5:$AR$10004)) | AS10012: =IF(COUNT('Data Entry'!$AS$5:$AS$10004)=0,"",MAX('Data Entry'!$AS$5:$AS$10004)) | AT10012: =IF(COUNT('Data Entry'!$AT$5:$AT$10004)=0,"",MAX('Data Entry'!$AT$5:$AT$10004)) | AU10012: =IF(COUNT('Data Entry'!$AU$5:$AU$10004)=0,"",MAX('Data Entry'!$AU$5:$AU$10004)) | AV10012: =IF(COUNT('Data Entry'!$AV$5:$AV$10004)=0,"",MAX('Data Entry'!$AV$5:$AV$10004)) | AW10012: =IF(COUNT('Data Entry'!$AW$5:$AW$10004)=0,"",MAX('Data Entry'!$AW$5:$AW$10004)) | AX10012: =IF(COUNT('Data Entry'!$AX$5:$AX$10004)=0,"",MAX('Data Entry'!$AX$5:$AX$10004)) | AY10012: =IF(COUNT('Data Entry'!$AY$5:$AY$10004)=0,"",MAX('Data Entry'!$AY$5:$AY$10004)) | AZ10012: =IF(COUNT('Data Entry'!$AZ$5:$AZ$10004)=0,"",MAX('Data Entry'!$AZ$5:$AZ$10004)) | BA10012: =IF(COUNT('Data Entry'!$BA$5:$BA$10004)=0,"",MAX('Data Entry'!$BA$5:$BA$10004)) | BB10012: =IF(COUNT('Data Entry'!$BB$5:$BB$10004)=0,"",MAX('Data Entry'!$BB$5:$BB$10004)) | BC10012: =IF(COUNT('Data Entry'!$BC$5:$BC$10004)=0,"",MAX('Data Entry'!$BC$5:$BC$10004)) | BD10012: =IF(COUNT('Data Entry'!$BD$5:$BD$10004)=0,"",MAX('Data Entry'!$BD$5:$BD$10004)) | BE10012: =IF(COUNT('Data Entry'!$BE$5:$BE$10004)=0,"",MAX('Data Entry'!$BE$5:$BE$10004))
A10013: Range (Max-Min) | H10013: =IF(COUNT('Data Entry'!$H$5:$H$10004)=0,"",MAX('Data Entry'!$H$5:$H$10004)-MIN('Data Entry'!$H$5:$H$10004)) | I10013: =IF(COUNT('Data Entry'!$I$5:$I$10004)=0,"",MAX('Data Entry'!$I$5:$I$10004)-MIN('Data Entry'!$I$5:$I$10004)) | J10013: =IF(COUNT('Data Entry'!$J$5:$J$10004)=0,"",MAX('Data Entry'!$J$5:$J$10004)-MIN('Data Entry'!$J$5:$J$10004)) | K10013: =IF(COUNT('Data Entry'!$K$5:$K$10004)=0,"",MAX('Data Entry'!$K$5:$K$10004)-MIN('Data Entry'!$K$5:$K$10004)) | L10013: =IF(COUNT('Data Entry'!$L$5:$L$10004)=0,"",MAX('Data Entry'!$L$5:$L$10004)-MIN('Data Entry'!$L$5:$L$10004)) | M10013: =IF(COUNT('Data Entry'!$M$5:$M$10004)=0,"",MAX('Data Entry'!$M$5:$M$10004)-MIN('Data Entry'!$M$5:$M$10004)) | N10013: =IF(COUNT('Data Entry'!$N$5:$N$10004)=0,"",MAX('Data Entry'!$N$5:$N$10004)-MIN('Data Entry'!$N$5:$N$10004)) | O10013: =IF(COUNT('Data Entry'!$O$5:$O$10004)=0,"",MAX('Data Entry'!$O$5:$O$10004)-MIN('Data Entry'!$O$5:$O$10004)) | P10013: =IF(COUNT('Data Entry'!$P$5:$P$10004)=0,"",MAX('Data Entry'!$P$5:$P$10004)-MIN('Data Entry'!$P$5:$P$10004)) | Q10013: =IF(COUNT('Data Entry'!$Q$5:$Q$10004)=0,"",MAX('Data Entry'!$Q$5:$Q$10004)-MIN('Data Entry'!$Q$5:$Q$10004)) | R10013: =IF(COUNT('Data Entry'!$R$5:$R$10004)=0,"",MAX('Data Entry'!$R$5:$R$10004)-MIN('Data Entry'!$R$5:$R$10004)) | S10013: =IF(COUNT('Data Entry'!$S$5:$S$10004)=0,"",MAX('Data Entry'!$S$5:$S$10004)-MIN('Data Entry'!$S$5:$S$10004)) | T10013: =IF(COUNT('Data Entry'!$T$5:$T$10004)=0,"",MAX('Data Entry'!$T$5:$T$10004)-MIN('Data Entry'!$T$5:$T$10004)) | U10013: =IF(COUNT('Data Entry'!$U$5:$U$10004)=0,"",MAX('Data Entry'!$U$5:$U$10004)-MIN('Data Entry'!$U$5:$U$10004)) | V10013: =IF(COUNT('Data Entry'!$V$5:$V$10004)=0,"",MAX('Data Entry'!$V$5:$V$10004)-MIN('Data Entry'!$V$5:$V$10004)) | W10013: =IF(COUNT('Data Entry'!$W$5:$W$10004)=0,"",MAX('Data Entry'!$W$5:$W$10004)-MIN('Data Entry'!$W$5:$W$10004)) | X10013: =IF(COUNT('Data Entry'!$X$5:$X$10004)=0,"",MAX('Data Entry'!$X$5:$X$10004)-MIN('Data Entry'!$X$5:$X$10004)) | Y10013: =IF(COUNT('Data Entry'!$Y$5:$Y$10004)=0,"",MAX('Data Entry'!$Y$5:$Y$10004)-MIN('Data Entry'!$Y$5:$Y$10004)) | Z10013: =IF(COUNT('Data Entry'!$Z$5:$Z$10004)=0,"",MAX('Data Entry'!$Z$5:$Z$10004)-MIN('Data Entry'!$Z$5:$Z$10004)) | AA10013: =IF(COUNT('Data Entry'!$AA$5:$AA$10004)=0,"",MAX('Data Entry'!$AA$5:$AA$10004)-MIN('Data Entry'!$AA$5:$AA$10004)) | AB10013: =IF(COUNT('Data Entry'!$AB$5:$AB$10004)=0,"",MAX('Data Entry'!$AB$5:$AB$10004)-MIN('Data Entry'!$AB$5:$AB$10004)) | AC10013: =IF(COUNT('Data Entry'!$AC$5:$AC$10004)=0,"",MAX('Data Entry'!$AC$5:$AC$10004)-MIN('Data Entry'!$AC$5:$AC$10004)) | AD10013: =IF(COUNT('Data Entry'!$AD$5:$AD$10004)=0,"",MAX('Data Entry'!$AD$5:$AD$10004)-MIN('Data Entry'!$AD$5:$AD$10004)) | AE10013: =IF(COUNT('Data Entry'!$AE$5:$AE$10004)=0,"",MAX('Data Entry'!$AE$5:$AE$10004)-MIN('Data Entry'!$AE$5:$AE$10004)) | AF10013: =IF(COUNT('Data Entry'!$AF$5:$AF$10004)=0,"",MAX('Data Entry'!$AF$5:$AF$10004)-MIN('Data Entry'!$AF$5:$AF$10004)) | AG10013: =IF(COUNT('Data Entry'!$AG$5:$AG$10004)=0,"",MAX('Data Entry'!$AG$5:$AG$10004)-MIN('Data Entry'!$AG$5:$AG$10004)) | AH10013: =IF(COUNT('Data Entry'!$AH$5:$AH$10004)=0,"",MAX('Data Entry'!$AH$5:$AH$10004)-MIN('Data Entry'!$AH$5:$AH$10004)) | AI10013: =IF(COUNT('Data Entry'!$AI$5:$AI$10004)=0,"",MAX('Data Entry'!$AI$5:$AI$10004)-MIN('Data Entry'!$AI$5:$AI$10004)) | AJ10013: =IF(COUNT('Data Entry'!$AJ$5:$AJ$10004)=0,"",MAX('Data Entry'!$AJ$5:$AJ$10004)-MIN('Data Entry'!$AJ$5:$AJ$10004)) | AK10013: =IF(COUNT('Data Entry'!$AK$5:$AK$10004)=0,"",MAX('Data Entry'!$AK$5:$AK$10004)-MIN('Data Entry'!$AK$5:$AK$10004)) | AL10013: =IF(COUNT('Data Entry'!$AL$5:$AL$10004)=0,"",MAX('Data Entry'!$AL$5:$AL$10004)-MIN('Data Entry'!$AL$5:$AL$10004)) | AM10013: =IF(COUNT('Data Entry'!$AM$5:$AM$10004)=0,"",MAX('Data Entry'!$AM$5:$AM$10004)-MIN('Data Entry'!$AM$5:$AM$10004)) | AN10013: =IF(COUNT('Data Entry'!$AN$5:$AN$10004)=0,"",MAX('Data Entry'!$AN$5:$AN$10004)-MIN('Data Entry'!$AN$5:$AN$10004)) | AO10013: =IF(COUNT('Data Entry'!$AO$5:$AO$10004)=0,"",MAX('Data Entry'!$AO$5:$AO$10004)-MIN('Data Entry'!$AO$5:$AO$10004)) | AP10013: =IF(COUNT('Data Entry'!$AP$5:$AP$10004)=0,"",MAX('Data Entry'!$AP$5:$AP$10004)-MIN('Data Entry'!$AP$5:$AP$10004)) | AQ10013: =IF(COUNT('Data Entry'!$AQ$5:$AQ$10004)=0,"",MAX('Data Entry'!$AQ$5:$AQ$10004)-MIN('Data Entry'!$AQ$5:$AQ$10004)) | AR10013: =IF(COUNT('Data Entry'!$AR$5:$AR$10004)=0,"",MAX('Data Entry'!$AR$5:$AR$10004)-MIN('Data Entry'!$AR$5:$AR$10004)) | AS10013: =IF(COUNT('Data Entry'!$AS$5:$AS$10004)=0,"",MAX('Data Entry'!$AS$5:$AS$10004)-MIN('Data Entry'!$AS$5:$AS$10004)) | AT10013: =IF(COUNT('Data Entry'!$AT$5:$AT$10004)=0,"",MAX('Data Entry'!$AT$5:$AT$10004)-MIN('Data Entry'!$AT$5:$AT$10004)) | AU10013: =IF(COUNT('Data Entry'!$AU$5:$AU$10004)=0,"",MAX('Data Entry'!$AU$5:$AU$10004)-MIN('Data Entry'!$AU$5:$AU$10004)) | AV10013: =IF(COUNT('Data Entry'!$AV$5:$AV$10004)=0,"",MAX('Data Entry'!$AV$5:$AV$10004)-MIN('Data Entry'!$AV$5:$AV$10004)) | AW10013: =IF(COUNT('Data Entry'!$AW$5:$AW$10004)=0,"",MAX('Data Entry'!$AW$5:$AW$10004)-MIN('Data Entry'!$AW$5:$AW$10004)) | AX10013: =IF(COUNT('Data Entry'!$AX$5:$AX$10004)=0,"",MAX('Data Entry'!$AX$5:$AX$10004)-MIN('Data Entry'!$AX$5:$AX$10004)) | AY10013: =IF(COUNT('Data Entry'!$AY$5:$AY$10004)=0,"",MAX('Data Entry'!$AY$5:$AY$10004)-MIN('Data Entry'!$AY$5:$AY$10004)) | AZ10013: =IF(COUNT('Data Entry'!$AZ$5:$AZ$10004)=0,"",MAX('Data Entry'!$AZ$5:$AZ$10004)-MIN('Data Entry'!$AZ$5:$AZ$10004)) | BA10013: =IF(COUNT('Data Entry'!$BA$5:$BA$10004)=0,"",MAX('Data Entry'!$BA$5:$BA$10004)-MIN('Data Entry'!$BA$5:$BA$10004)) | BB10013: =IF(COUNT('Data Entry'!$BB$5:$BB$10004)=0,"",MAX('Data Entry'!$BB$5:$BB$10004)-MIN('Data Entry'!$BB$5:$BB$10004)) | BC10013: =IF(COUNT('Data Entry'!$BC$5:$BC$10004)=0,"",MAX('Data Entry'!$BC$5:$BC$10004)-MIN('Data Entry'!$BC$5:$BC$10004)) | BD10013: =IF(COUNT('Data Entry'!$BD$5:$BD$10004)=0,"",MAX('Data Entry'!$BD$5:$BD$10004)-MIN('Data Entry'!$BD$5:$BD$10004)) | BE10013: =IF(COUNT('Data Entry'!$BE$5:$BE$10004)=0,"",MAX('Data Entry'!$BE$5:$BE$10004)-MIN('Data Entry'!$BE$5:$BE$10004))
A10014: Std Dev (overall) | H10014: =IF(COUNT('Data Entry'!$H$5:$H$10004)<2,"",STDEV('Data Entry'!$H$5:$H$10004)) | I10014: =IF(COUNT('Data Entry'!$I$5:$I$10004)<2,"",STDEV('Data Entry'!$I$5:$I$10004)) | J10014: =IF(COUNT('Data Entry'!$J$5:$J$10004)<2,"",STDEV('Data Entry'!$J$5:$J$10004)) | K10014: =IF(COUNT('Data Entry'!$K$5:$K$10004)<2,"",STDEV('Data Entry'!$K$5:$K$10004)) | L10014: =IF(COUNT('Data Entry'!$L$5:$L$10004)<2,"",STDEV('Data Entry'!$L$5:$L$10004)) | M10014: =IF(COUNT('Data Entry'!$M$5:$M$10004)<2,"",STDEV('Data Entry'!$M$5:$M$10004)) | N10014: =IF(COUNT('Data Entry'!$N$5:$N$10004)<2,"",STDEV('Data Entry'!$N$5:$N$10004)) | O10014: =IF(COUNT('Data Entry'!$O$5:$O$10004)<2,"",STDEV('Data Entry'!$O$5:$O$10004)) | P10014: =IF(COUNT('Data Entry'!$P$5:$P$10004)<2,"",STDEV('Data Entry'!$P$5:$P$10004)) | Q10014: =IF(COUNT('Data Entry'!$Q$5:$Q$10004)<2,"",STDEV('Data Entry'!$Q$5:$Q$10004)) | R10014: =IF(COUNT('Data Entry'!$R$5:$R$10004)<2,"",STDEV('Data Entry'!$R$5:$R$10004)) | S10014: =IF(COUNT('Data Entry'!$S$5:$S$10004)<2,"",STDEV('Data Entry'!$S$5:$S$10004)) | T10014: =IF(COUNT('Data Entry'!$T$5:$T$10004)<2,"",STDEV('Data Entry'!$T$5:$T$10004)) | U10014: =IF(COUNT('Data Entry'!$U$5:$U$10004)<2,"",STDEV('Data Entry'!$U$5:$U$10004)) | V10014: =IF(COUNT('Data Entry'!$V$5:$V$10004)<2,"",STDEV('Data Entry'!$V$5:$V$10004)) | W10014: =IF(COUNT('Data Entry'!$W$5:$W$10004)<2,"",STDEV('Data Entry'!$W$5:$W$10004)) | X10014: =IF(COUNT('Data Entry'!$X$5:$X$10004)<2,"",STDEV('Data Entry'!$X$5:$X$10004)) | Y10014: =IF(COUNT('Data Entry'!$Y$5:$Y$10004)<2,"",STDEV('Data Entry'!$Y$5:$Y$10004)) | Z10014: =IF(COUNT('Data Entry'!$Z$5:$Z$10004)<2,"",STDEV('Data Entry'!$Z$5:$Z$10004)) | AA10014: =IF(COUNT('Data Entry'!$AA$5:$AA$10004)<2,"",STDEV('Data Entry'!$AA$5:$AA$10004)) | AB10014: =IF(COUNT('Data Entry'!$AB$5:$AB$10004)<2,"",STDEV('Data Entry'!$AB$5:$AB$10004)) | AC10014: =IF(COUNT('Data Entry'!$AC$5:$AC$10004)<2,"",STDEV('Data Entry'!$AC$5:$AC$10004)) | AD10014: =IF(COUNT('Data Entry'!$AD$5:$AD$10004)<2,"",STDEV('Data Entry'!$AD$5:$AD$10004)) | AE10014: =IF(COUNT('Data Entry'!$AE$5:$AE$10004)<2,"",STDEV('Data Entry'!$AE$5:$AE$10004)) | AF10014: =IF(COUNT('Data Entry'!$AF$5:$AF$10004)<2,"",STDEV('Data Entry'!$AF$5:$AF$10004)) | AG10014: =IF(COUNT('Data Entry'!$AG$5:$AG$10004)<2,"",STDEV('Data Entry'!$AG$5:$AG$10004)) | AH10014: =IF(COUNT('Data Entry'!$AH$5:$AH$10004)<2,"",STDEV('Data Entry'!$AH$5:$AH$10004)) | AI10014: =IF(COUNT('Data Entry'!$AI$5:$AI$10004)<2,"",STDEV('Data Entry'!$AI$5:$AI$10004)) | AJ10014: =IF(COUNT('Data Entry'!$AJ$5:$AJ$10004)<2,"",STDEV('Data Entry'!$AJ$5:$AJ$10004)) | AK10014: =IF(COUNT('Data Entry'!$AK$5:$AK$10004)<2,"",STDEV('Data Entry'!$AK$5:$AK$10004)) | AL10014: =IF(COUNT('Data Entry'!$AL$5:$AL$10004)<2,"",STDEV('Data Entry'!$AL$5:$AL$10004)) | AM10014: =IF(COUNT('Data Entry'!$AM$5:$AM$10004)<2,"",STDEV('Data Entry'!$AM$5:$AM$10004)) | AN10014: =IF(COUNT('Data Entry'!$AN$5:$AN$10004)<2,"",STDEV('Data Entry'!$AN$5:$AN$10004)) | AO10014: =IF(COUNT('Data Entry'!$AO$5:$AO$10004)<2,"",STDEV('Data Entry'!$AO$5:$AO$10004)) | AP10014: =IF(COUNT('Data Entry'!$AP$5:$AP$10004)<2,"",STDEV('Data Entry'!$AP$5:$AP$10004)) | AQ10014: =IF(COUNT('Data Entry'!$AQ$5:$AQ$10004)<2,"",STDEV('Data Entry'!$AQ$5:$AQ$10004)) | AR10014: =IF(COUNT('Data Entry'!$AR$5:$AR$10004)<2,"",STDEV('Data Entry'!$AR$5:$AR$10004)) | AS10014: =IF(COUNT('Data Entry'!$AS$5:$AS$10004)<2,"",STDEV('Data Entry'!$AS$5:$AS$10004)) | AT10014: =IF(COUNT('Data Entry'!$AT$5:$AT$10004)<2,"",STDEV('Data Entry'!$AT$5:$AT$10004)) | AU10014: =IF(COUNT('Data Entry'!$AU$5:$AU$10004)<2,"",STDEV('Data Entry'!$AU$5:$AU$10004)) | AV10014: =IF(COUNT('Data Entry'!$AV$5:$AV$10004)<2,"",STDEV('Data Entry'!$AV$5:$AV$10004)) | AW10014: =IF(COUNT('Data Entry'!$AW$5:$AW$10004)<2,"",STDEV('Data Entry'!$AW$5:$AW$10004)) | AX10014: =IF(COUNT('Data Entry'!$AX$5:$AX$10004)<2,"",STDEV('Data Entry'!$AX$5:$AX$10004)) | AY10014: =IF(COUNT('Data Entry'!$AY$5:$AY$10004)<2,"",STDEV('Data Entry'!$AY$5:$AY$10004)) | AZ10014: =IF(COUNT('Data Entry'!$AZ$5:$AZ$10004)<2,"",STDEV('Data Entry'!$AZ$5:$AZ$10004)) | BA10014: =IF(COUNT('Data Entry'!$BA$5:$BA$10004)<2,"",STDEV('Data Entry'!$BA$5:$BA$10004)) | BB10014: =IF(COUNT('Data Entry'!$BB$5:$BB$10004)<2,"",STDEV('Data Entry'!$BB$5:$BB$10004)) | BC10014: =IF(COUNT('Data Entry'!$BC$5:$BC$10004)<2,"",STDEV('Data Entry'!$BC$5:$BC$10004)) | BD10014: =IF(COUNT('Data Entry'!$BD$5:$BD$10004)<2,"",STDEV('Data Entry'!$BD$5:$BD$10004)) | BE10014: =IF(COUNT('Data Entry'!$BE$5:$BE$10004)<2,"",STDEV('Data Entry'!$BE$5:$BE$10004))
A10015: mR-bar | H10015: =IF(COUNT('Data Entry'!$H$5:$H$10004)<2,"",SUMPRODUCT(('Data Entry'!$H$6:$H$10004<>"")*('Data Entry'!$H$5:$H$10003<>"")*ABS('Data Entry'!$H$6:$H$10004-'Data Entry'!$H$5:$H$10003))/MAX(1,SUMPRODUCT(('Data Entry'!$H$6:$H$10004<>"")*('Data Entry'!$H$5:$H$10003<>"")*1))) | I10015: =IF(COUNT('Data Entry'!$I$5:$I$10004)<2,"",SUMPRODUCT(('Data Entry'!$I$6:$I$10004<>"")*('Data Entry'!$I$5:$I$10003<>"")*ABS('Data Entry'!$I$6:$I$10004-'Data Entry'!$I$5:$I$10003))/MAX(1,SUMPRODUCT(('Data Entry'!$I$6:$I$10004<>"")*('Data Entry'!$I$5:$I$10003<>"")*1))) | J10015: =IF(COUNT('Data Entry'!$J$5:$J$10004)<2,"",SUMPRODUCT(('Data Entry'!$J$6:$J$10004<>"")*('Data Entry'!$J$5:$J$10003<>"")*ABS('Data Entry'!$J$6:$J$10004-'Data Entry'!$J$5:$J$10003))/MAX(1,SUMPRODUCT(('Data Entry'!$J$6:$J$10004<>"")*('Data Entry'!$J$5:$J$10003<>"")*1))) | K10015: =IF(COUNT('Data Entry'!$K$5:$K$10004)<2,"",SUMPRODUCT(('Data Entry'!$K$6:$K$10004<>"")*('Data Entry'!$K$5:$K$10003<>"")*ABS('Data Entry'!$K$6:$K$10004-'Data Entry'!$K$5:$K$10003))/MAX(1,SUMPRODUCT(('Data Entry'!$K$6:$K$10004<>"")*('Data Entry'!$K$5:$K$10003<>"")*1))) | L10015: =IF(COUNT('Data Entry'!$L$5:$L$10004)<2,"",SUMPRODUCT(('Data Entry'!$L$6:$L$10004<>"")*('Data Entry'!$L$5:$L$10003<>"")*ABS('Data Entry'!$L$6:$L$10004-'Data Entry'!$L$5:$L$10003))/MAX(1,SUMPRODUCT(('Data Entry'!$L$6:$L$10004<>"")*('Data Entry'!$L$5:$L$10003<>"")*1))) | M10015: =IF(COUNT('Data Entry'!$M$5:$M$10004)<2,"",SUMPRODUCT(('Data Entry'!$M$6:$M$10004<>"")*('Data Entry'!$M$5:$M$10003<>"")*ABS('Data Entry'!$M$6:$M$10004-'Data Entry'!$M$5:$M$10003))/MAX(1,SUMPRODUCT(('Data Entry'!$M$6:$M$10004<>"")*('Data Entry'!$M$5:$M$10003<>"")*1))) | N10015: =IF(COUNT('Data Entry'!$N$5:$N$10004)<2,"",SUMPRODUCT(('Data Entry'!$N$6:$N$10004<>"")*('Data Entry'!$N$5:$N$10003<>"")*ABS('Data Entry'!$N$6:$N$10004-'Data Entry'!$N$5:$N$10003))/MAX(1,SUMPRODUCT(('Data Entry'!$N$6:$N$10004<>"")*('Data Entry'!$N$5:$N$10003<>"")*1))) | O10015: =IF(COUNT('Data Entry'!$O$5:$O$10004)<2,"",SUMPRODUCT(('Data Entry'!$O$6:$O$10004<>"")*('Data Entry'!$O$5:$O$10003<>"")*ABS('Data Entry'!$O$6:$O$10004-'Data Entry'!$O$5:$O$10003))/MAX(1,SUMPRODUCT(('Data Entry'!$O$6:$O$10004<>"")*('Data Entry'!$O$5:$O$10003<>"")*1))) | P10015: =IF(COUNT('Data Entry'!$P$5:$P$10004)<2,"",SUMPRODUCT(('Data Entry'!$P$6:$P$10004<>"")*('Data Entry'!$P$5:$P$10003<>"")*ABS('Data Entry'!$P$6:$P$10004-'Data Entry'!$P$5:$P$10003))/MAX(1,SUMPRODUCT(('Data Entry'!$P$6:$P$10004<>"")*('Data Entry'!$P$5:$P$10003<>"")*1))) | Q10015: =IF(COUNT('Data Entry'!$Q$5:$Q$10004)<2,"",SUMPRODUCT(('Data Entry'!$Q$6:$Q$10004<>"")*('Data Entry'!$Q$5:$Q$10003<>"")*ABS('Data Entry'!$Q$6:$Q$10004-'Data Entry'!$Q$5:$Q$10003))/MAX(1,SUMPRODUCT(('Data Entry'!$Q$6:$Q$10004<>"")*('Data Entry'!$Q$5:$Q$10003<>"")*1))) | R10015: =IF(COUNT('Data Entry'!$R$5:$R$10004)<2,"",SUMPRODUCT(('Data Entry'!$R$6:$R$10004<>"")*('Data Entry'!$R$5:$R$10003<>"")*ABS('Data Entry'!$R$6:$R$10004-'Data Entry'!$R$5:$R$10003))/MAX(1,SUMPRODUCT(('Data Entry'!$R$6:$R$10004<>"")*('Data Entry'!$R$5:$R$10003<>"")*1))) | S10015: =IF(COUNT('Data Entry'!$S$5:$S$10004)<2,"",SUMPRODUCT(('Data Entry'!$S$6:$S$10004<>"")*('Data Entry'!$S$5:$S$10003<>"")*ABS('Data Entry'!$S$6:$S$10004-'Data Entry'!$S$5:$S$10003))/MAX(1,SUMPRODUCT(('Data Entry'!$S$6:$S$10004<>"")*('Data Entry'!$S$5:$S$10003<>"")*1))) | T10015: =IF(COUNT('Data Entry'!$T$5:$T$10004)<2,"",SUMPRODUCT(('Data Entry'!$T$6:$T$10004<>"")*('Data Entry'!$T$5:$T$10003<>"")*ABS('Data Entry'!$T$6:$T$10004-'Data Entry'!$T$5:$T$10003))/MAX(1,SUMPRODUCT(('Data Entry'!$T$6:$T$10004<>"")*('Data Entry'!$T$5:$T$10003<>"")*1))) | U10015: =IF(COUNT('Data Entry'!$U$5:$U$10004)<2,"",SUMPRODUCT(('Data Entry'!$U$6:$U$10004<>"")*('Data Entry'!$U$5:$U$10003<>"")*ABS('Data Entry'!$U$6:$U$10004-'Data Entry'!$U$5:$U$10003))/MAX(1,SUMPRODUCT(('Data Entry'!$U$6:$U$10004<>"")*('Data Entry'!$U$5:$U$10003<>"")*1))) | V10015: =IF(COUNT('Data Entry'!$V$5:$V$10004)<2,"",SUMPRODUCT(('Data Entry'!$V$6:$V$10004<>"")*('Data Entry'!$V$5:$V$10003<>"")*ABS('Data Entry'!$V$6:$V$10004-'Data Entry'!$V$5:$V$10003))/MAX(1,SUMPRODUCT(('Data Entry'!$V$6:$V$10004<>"")*('Data Entry'!$V$5:$V$10003<>"")*1))) | W10015: =IF(COUNT('Data Entry'!$W$5:$W$10004)<2,"",SUMPRODUCT(('Data Entry'!$W$6:$W$10004<>"")*('Data Entry'!$W$5:$W$10003<>"")*ABS('Data Entry'!$W$6:$W$10004-'Data Entry'!$W$5:$W$10003))/MAX(1,SUMPRODUCT(('Data Entry'!$W$6:$W$10004<>"")*('Data Entry'!$W$5:$W$10003<>"")*1))) | X10015: =IF(COUNT('Data Entry'!$X$5:$X$10004)<2,"",SUMPRODUCT(('Data Entry'!$X$6:$X$10004<>"")*('Data Entry'!$X$5:$X$10003<>"")*ABS('Data Entry'!$X$6:$X$10004-'Data Entry'!$X$5:$X$10003))/MAX(1,SUMPRODUCT(('Data Entry'!$X$6:$X$10004<>"")*('Data Entry'!$X$5:$X$10003<>"")*1))) | Y10015: =IF(COUNT('Data Entry'!$Y$5:$Y$10004)<2,"",SUMPRODUCT(('Data Entry'!$Y$6:$Y$10004<>"")*('Data Entry'!$Y$5:$Y$10003<>"")*ABS('Data Entry'!$Y$6:$Y$10004-'Data Entry'!$Y$5:$Y$10003))/MAX(1,SUMPRODUCT(('Data Entry'!$Y$6:$Y$10004<>"")*('Data Entry'!$Y$5:$Y$10003<>"")*1))) | Z10015: =IF(COUNT('Data Entry'!$Z$5:$Z$10004)<2,"",SUMPRODUCT(('Data Entry'!$Z$6:$Z$10004<>"")*('Data Entry'!$Z$5:$Z$10003<>"")*ABS('Data Entry'!$Z$6:$Z$10004-'Data Entry'!$Z$5:$Z$10003))/MAX(1,SUMPRODUCT(('Data Entry'!$Z$6:$Z$10004<>"")*('Data Entry'!$Z$5:$Z$10003<>"")*1))) | AA10015: =IF(COUNT('Data Entry'!$AA$5:$AA$10004)<2,"",SUMPRODUCT(('Data Entry'!$AA$6:$AA$10004<>"")*('Data Entry'!$AA$5:$AA$10003<>"")*ABS('Data Entry'!$AA$6:$AA$10004-'Data Entry'!$AA$5:$AA$10003))/MAX(1,SUMPRODUCT(('Data Entry'!$AA$6:$AA$10004<>"")*('Data Entry'!$AA$5:$AA$10003<>"")*1))) | AB10015: =IF(COUNT('Data Entry'!$AB$5:$AB$10004)<2,"",SUMPRODUCT(('Data Entry'!$AB$6:$AB$10004<>"")*('Data Entry'!$AB$5:$AB$10003<>"")*ABS('Data Entry'!$AB$6:$AB$10004-'Data Entry'!$AB$5:$AB$10003))/MAX(1,SUMPRODUCT(('Data Entry'!$AB$6:$AB$10004<>"")*('Data Entry'!$AB$5:$AB$10003<>"")*1))) | AC10015: =IF(COUNT('Data Entry'!$AC$5:$AC$10004)<2,"",SUMPRODUCT(('Data Entry'!$AC$6:$AC$10004<>"")*('Data Entry'!$AC$5:$AC$10003<>"")*ABS('Data Entry'!$AC$6:$AC$10004-'Data Entry'!$AC$5:$AC$10003))/MAX(1,SUMPRODUCT(('Data Entry'!$AC$6:$AC$10004<>"")*('Data Entry'!$AC$5:$AC$10003<>"")*1))) | AD10015: =IF(COUNT('Data Entry'!$AD$5:$AD$10004)<2,"",SUMPRODUCT(('Data Entry'!$AD$6:$AD$10004<>"")*('Data Entry'!$AD$5:$AD$10003<>"")*ABS('Data Entry'!$AD$6:$AD$10004-'Data Entry'!$AD$5:$AD$10003))/MAX(1,SUMPRODUCT(('Data Entry'!$AD$6:$AD$10004<>"")*('Data Entry'!$AD$5:$AD$10003<>"")*1))) | AE10015: =IF(COUNT('Data Entry'!$AE$5:$AE$10004)<2,"",SUMPRODUCT(('Data Entry'!$AE$6:$AE$10004<>"")*('Data Entry'!$AE$5:$AE$10003<>"")*ABS('Data Entry'!$AE$6:$AE$10004-'Data Entry'!$AE$5:$AE$10003))/MAX(1,SUMPRODUCT(('Data Entry'!$AE$6:$AE$10004<>"")*('Data Entry'!$AE$5:$AE$10003<>"")*1))) | AF10015: =IF(COUNT('Data Entry'!$AF$5:$AF$10004)<2,"",SUMPRODUCT(('Data Entry'!$AF$6:$AF$10004<>"")*('Data Entry'!$AF$5:$AF$10003<>"")*ABS('Data Entry'!$AF$6:$AF$10004-'Data Entry'!$AF$5:$AF$10003))/MAX(1,SUMPRODUCT(('Data Entry'!$AF$6:$AF$10004<>"")*('Data Entry'!$AF$5:$AF$10003<>"")*1))) | AG10015: =IF(COUNT('Data Entry'!$AG$5:$AG$10004)<2,"",SUMPRODUCT(('Data Entry'!$AG$6:$AG$10004<>"")*('Data Entry'!$AG$5:$AG$10003<>"")*ABS('Data Entry'!$AG$6:$AG$10004-'Data Entry'!$AG$5:$AG$10003))/MAX(1,SUMPRODUCT(('Data Entry'!$AG$6:$AG$10004<>"")*('Data Entry'!$AG$5:$AG$10003<>"")*1))) | AH10015: =IF(COUNT('Data Entry'!$AH$5:$AH$10004)<2,"",SUMPRODUCT(('Data Entry'!$AH$6:$AH$10004<>"")*('Data Entry'!$AH$5:$AH$10003<>"")*ABS('Data Entry'!$AH$6:$AH$10004-'Data Entry'!$AH$5:$AH$10003))/MAX(1,SUMPRODUCT(('Data Entry'!$AH$6:$AH$10004<>"")*('Data Entry'!$AH$5:$AH$10003<>"")*1))) | AI10015: =IF(COUNT('Data Entry'!$AI$5:$AI$10004)<2,"",SUMPRODUCT(('Data Entry'!$AI$6:$AI$10004<>"")*('Data Entry'!$AI$5:$AI$10003<>"")*ABS('Data Entry'!$AI$6:$AI$10004-'Data Entry'!$AI$5:$AI$10003))/MAX(1,SUMPRODUCT(('Data Entry'!$AI$6:$AI$10004<>"")*('Data Entry'!$AI$5:$AI$10003<>"")*1))) | AJ10015: =IF(COUNT('Data Entry'!$AJ$5:$AJ$10004)<2,"",SUMPRODUCT(('Data Entry'!$AJ$6:$AJ$10004<>"")*('Data Entry'!$AJ$5:$AJ$10003<>"")*ABS('Data Entry'!$AJ$6:$AJ$10004-'Data Entry'!$AJ$5:$AJ$10003))/MAX(1,SUMPRODUCT(('Data Entry'!$AJ$6:$AJ$10004<>"")*('Data Entry'!$AJ$5:$AJ$10003<>"")*1))) | AK10015: =IF(COUNT('Data Entry'!$AK$5:$AK$10004)<2,"",SUMPRODUCT(('Data Entry'!$AK$6:$AK$10004<>"")*('Data Entry'!$AK$5:$AK$10003<>"")*ABS('Data Entry'!$AK$6:$AK$10004-'Data Entry'!$AK$5:$AK$10003))/MAX(1,SUMPRODUCT(('Data Entry'!$AK$6:$AK$10004<>"")*('Data Entry'!$AK$5:$AK$10003<>"")*1))) | AL10015: =IF(COUNT('Data Entry'!$AL$5:$AL$10004)<2,"",SUMPRODUCT(('Data Entry'!$AL$6:$AL$10004<>"")*('Data Entry'!$AL$5:$AL$10003<>"")*ABS('Data Entry'!$AL$6:$AL$10004-'Data Entry'!$AL$5:$AL$10003))/MAX(1,SUMPRODUCT(('Data Entry'!$AL$6:$AL$10004<>"")*('Data Entry'!$AL$5:$AL$10003<>"")*1))) | AM10015: =IF(COUNT('Data Entry'!$AM$5:$AM$10004)<2,"",SUMPRODUCT(('Data Entry'!$AM$6:$AM$10004<>"")*('Data Entry'!$AM$5:$AM$10003<>"")*ABS('Data Entry'!$AM$6:$AM$10004-'Data Entry'!$AM$5:$AM$10003))/MAX(1,SUMPRODUCT(('Data Entry'!$AM$6:$AM$10004<>"")*('Data Entry'!$AM$5:$AM$10003<>"")*1))) | AN10015: =IF(COUNT('Data Entry'!$AN$5:$AN$10004)<2,"",SUMPRODUCT(('Data Entry'!$AN$6:$AN$10004<>"")*('Data Entry'!$AN$5:$AN$10003<>"")*ABS('Data Entry'!$AN$6:$AN$10004-'Data Entry'!$AN$5:$AN$10003))/MAX(1,SUMPRODUCT(('Data Entry'!$AN$6:$AN$10004<>"")*('Data Entry'!$AN$5:$AN$10003<>"")*1))) | AO10015: =IF(COUNT('Data Entry'!$AO$5:$AO$10004)<2,"",SUMPRODUCT(('Data Entry'!$AO$6:$AO$10004<>"")*('Data Entry'!$AO$5:$AO$10003<>"")*ABS('Data Entry'!$AO$6:$AO$10004-'Data Entry'!$AO$5:$AO$10003))/MAX(1,SUMPRODUCT(('Data Entry'!$AO$6:$AO$10004<>"")*('Data Entry'!$AO$5:$AO$10003<>"")*1))) | AP10015: =IF(COUNT('Data Entry'!$AP$5:$AP$10004)<2,"",SUMPRODUCT(('Data Entry'!$AP$6:$AP$10004<>"")*('Data Entry'!$AP$5:$AP$10003<>"")*ABS('Data Entry'!$AP$6:$AP$10004-'Data Entry'!$AP$5:$AP$10003))/MAX(1,SUMPRODUCT(('Data Entry'!$AP$6:$AP$10004<>"")*('Data Entry'!$AP$5:$AP$10003<>"")*1))) | AQ10015: =IF(COUNT('Data Entry'!$AQ$5:$AQ$10004)<2,"",SUMPRODUCT(('Data Entry'!$AQ$6:$AQ$10004<>"")*('Data Entry'!$AQ$5:$AQ$10003<>"")*ABS('Data Entry'!$AQ$6:$AQ$10004-'Data Entry'!$AQ$5:$AQ$10003))/MAX(1,SUMPRODUCT(('Data Entry'!$AQ$6:$AQ$10004<>"")*('Data Entry'!$AQ$5:$AQ$10003<>"")*1))) | AR10015: =IF(COUNT('Data Entry'!$AR$5:$AR$10004)<2,"",SUMPRODUCT(('Data Entry'!$AR$6:$AR$10004<>"")*('Data Entry'!$AR$5:$AR$10003<>"")*ABS('Data Entry'!$AR$6:$AR$10004-'Data Entry'!$AR$5:$AR$10003))/MAX(1,SUMPRODUCT(('Data Entry'!$AR$6:$AR$10004<>"")*('Data Entry'!$AR$5:$AR$10003<>"")*1))) | AS10015: =IF(COUNT('Data Entry'!$AS$5:$AS$10004)<2,"",SUMPRODUCT(('Data Entry'!$AS$6:$AS$10004<>"")*('Data Entry'!$AS$5:$AS$10003<>"")*ABS('Data Entry'!$AS$6:$AS$10004-'Data Entry'!$AS$5:$AS$10003))/MAX(1,SUMPRODUCT(('Data Entry'!$AS$6:$AS$10004<>"")*('Data Entry'!$AS$5:$AS$10003<>"")*1))) | AT10015: =IF(COUNT('Data Entry'!$AT$5:$AT$10004)<2,"",SUMPRODUCT(('Data Entry'!$AT$6:$AT$10004<>"")*('Data Entry'!$AT$5:$AT$10003<>"")*ABS('Data Entry'!$AT$6:$AT$10004-'Data Entry'!$AT$5:$AT$10003))/MAX(1,SUMPRODUCT(('Data Entry'!$AT$6:$AT$10004<>"")*('Data Entry'!$AT$5:$AT$10003<>"")*1))) | AU10015: =IF(COUNT('Data Entry'!$AU$5:$AU$10004)<2,"",SUMPRODUCT(('Data Entry'!$AU$6:$AU$10004<>"")*('Data Entry'!$AU$5:$AU$10003<>"")*ABS('Data Entry'!$AU$6:$AU$10004-'Data Entry'!$AU$5:$AU$10003))/MAX(1,SUMPRODUCT(('Data Entry'!$AU$6:$AU$10004<>"")*('Data Entry'!$AU$5:$AU$10003<>"")*1))) | AV10015: =IF(COUNT('Data Entry'!$AV$5:$AV$10004)<2,"",SUMPRODUCT(('Data Entry'!$AV$6:$AV$10004<>"")*('Data Entry'!$AV$5:$AV$10003<>"")*ABS('Data Entry'!$AV$6:$AV$10004-'Data Entry'!$AV$5:$AV$10003))/MAX(1,SUMPRODUCT(('Data Entry'!$AV$6:$AV$10004<>"")*('Data Entry'!$AV$5:$AV$10003<>"")*1))) | AW10015: =IF(COUNT('Data Entry'!$AW$5:$AW$10004)<2,"",SUMPRODUCT(('Data Entry'!$AW$6:$AW$10004<>"")*('Data Entry'!$AW$5:$AW$10003<>"")*ABS('Data Entry'!$AW$6:$AW$10004-'Data Entry'!$AW$5:$AW$10003))/MAX(1,SUMPRODUCT(('Data Entry'!$AW$6:$AW$10004<>"")*('Data Entry'!$AW$5:$AW$10003<>"")*1))) | AX10015: =IF(COUNT('Data Entry'!$AX$5:$AX$10004)<2,"",SUMPRODUCT(('Data Entry'!$AX$6:$AX$10004<>"")*('Data Entry'!$AX$5:$AX$10003<>"")*ABS('Data Entry'!$AX$6:$AX$10004-'Data Entry'!$AX$5:$AX$10003))/MAX(1,SUMPRODUCT(('Data Entry'!$AX$6:$AX$10004<>"")*('Data Entry'!$AX$5:$AX$10003<>"")*1))) | AY10015: =IF(COUNT('Data Entry'!$AY$5:$AY$10004)<2,"",SUMPRODUCT(('Data Entry'!$AY$6:$AY$10004<>"")*('Data Entry'!$AY$5:$AY$10003<>"")*ABS('Data Entry'!$AY$6:$AY$10004-'Data Entry'!$AY$5:$AY$10003))/MAX(1,SUMPRODUCT(('Data Entry'!$AY$6:$AY$10004<>"")*('Data Entry'!$AY$5:$AY$10003<>"")*1))) | AZ10015: =IF(COUNT('Data Entry'!$AZ$5:$AZ$10004)<2,"",SUMPRODUCT(('Data Entry'!$AZ$6:$AZ$10004<>"")*('Data Entry'!$AZ$5:$AZ$10003<>"")*ABS('Data Entry'!$AZ$6:$AZ$10004-'Data Entry'!$AZ$5:$AZ$10003))/MAX(1,SUMPRODUCT(('Data Entry'!$AZ$6:$AZ$10004<>"")*('Data Entry'!$AZ$5:$AZ$10003<>"")*1))) | BA10015: =IF(COUNT('Data Entry'!$BA$5:$BA$10004)<2,"",SUMPRODUCT(('Data Entry'!$BA$6:$BA$10004<>"")*('Data Entry'!$BA$5:$BA$10003<>"")*ABS('Data Entry'!$BA$6:$BA$10004-'Data Entry'!$BA$5:$BA$10003))/MAX(1,SUMPRODUCT(('Data Entry'!$BA$6:$BA$10004<>"")*('Data Entry'!$BA$5:$BA$10003<>"")*1))) | BB10015: =IF(COUNT('Data Entry'!$BB$5:$BB$10004)<2,"",SUMPRODUCT(('Data Entry'!$BB$6:$BB$10004<>"")*('Data Entry'!$BB$5:$BB$10003<>"")*ABS('Data Entry'!$BB$6:$BB$10004-'Data Entry'!$BB$5:$BB$10003))/MAX(1,SUMPRODUCT(('Data Entry'!$BB$6:$BB$10004<>"")*('Data Entry'!$BB$5:$BB$10003<>"")*1))) | BC10015: =IF(COUNT('Data Entry'!$BC$5:$BC$10004)<2,"",SUMPRODUCT(('Data Entry'!$BC$6:$BC$10004<>"")*('Data Entry'!$BC$5:$BC$10003<>"")*ABS('Data Entry'!$BC$6:$BC$10004-'Data Entry'!$BC$5:$BC$10003))/MAX(1,SUMPRODUCT(('Data Entry'!$BC$6:$BC$10004<>"")*('Data Entry'!$BC$5:$BC$10003<>"")*1))) | BD10015: =IF(COUNT('Data Entry'!$BD$5:$BD$10004)<2,"",SUMPRODUCT(('Data Entry'!$BD$6:$BD$10004<>"")*('Data Entry'!$BD$5:$BD$10003<>"")*ABS('Data Entry'!$BD$6:$BD$10004-'Data Entry'!$BD$5:$BD$10003))/MAX(1,SUMPRODUCT(('Data Entry'!$BD$6:$BD$10004<>"")*('Data Entry'!$BD$5:$BD$10003<>"")*1))) | BE10015: =IF(COUNT('Data Entry'!$BE$5:$BE$10004)<2,"",SUMPRODUCT(('Data Entry'!$BE$6:$BE$10004<>"")*('Data Entry'!$BE$5:$BE$10003<>"")*ABS('Data Entry'!$BE$6:$BE$10004-'Data Entry'!$BE$5:$BE$10003))/MAX(1,SUMPRODUCT(('Data Entry'!$BE$6:$BE$10004<>"")*('Data Entry'!$BE$5:$BE$10003<>"")*1)))
A10016: Sigma (within) | H10016: =IF(H10015="","",H10015/1.128) | I10016: =IF(I10015="","",I10015/1.128) | J10016: =IF(J10015="","",J10015/1.128) | K10016: =IF(K10015="","",K10015/1.128) | L10016: =IF(L10015="","",L10015/1.128) | M10016: =IF(M10015="","",M10015/1.128) | N10016: =IF(N10015="","",N10015/1.128) | O10016: =IF(O10015="","",O10015/1.128) | ... BE10016: =IF(BE10015="","",BE10015/1.128)
A10017: UCL (X) | H10017: =IF(H10015="","",H10010+2.66*H10015) | I10017: =IF(I10015="","",I10010+2.66*I10015) | J10017: =IF(J10015="","",J10010+2.66*J10015) | K10017: =IF(K10015="","",K10010+2.66*K10015) | L10017: =IF(L10015="","",L10010+2.66*L10015) | M10017: =IF(M10015="","",M10010+2.66*M10015) | N10017: =IF(N10015="","",N10010+2.66*N10015) | O10017: =IF(O10015="","",O10010+2.66*O10015) | ... BE10017: =IF(BE10015="","",BE10010+2.66*BE10015)
...

Sheet Data Collection Form
A1: SPC DATA COLLECTION SHEET | L1: ="Doc: "&Settings!B9&" Rev "&Settings!B10
A2: =Settings!B8
A4: Part No.: | H4: Operation:
A5: Machine / Cell: | H5: Gauge ID:
A6: Operator: | H6: Shift:
A7: Date: | H7: Sample frequency:
A9: CHARACTERISTICS
A10: Characteristic | D10: =IF(Settings!B17="","-",Settings!B17) | E10: =IF(Settings!B18="","-",Settings!B18) | F10: =IF(Settings!B19="","-",Settings!B19) | G10: =IF(Settings!B20="","-",Settings!B20) | H10: =IF(Settings!B21="","-",Settings!B21) | I10: =IF(Settings!B22="","-",Settings!B22) | J10: =IF(Settings!B23="","-",Settings!B23) | K10: =IF(Settings!B24="","-",Settings!B24) | L10: =IF(Settings!B25="","-",Settings!B25) | M10: =IF(Settings!B26="","-",Settings!B26)
A11: Nominal | D11: =IF(Settings!C17="","-",Settings!C17) | E11: =IF(Settings!C18="","-",Settings!C18) | F11: =IF(Settings!C19="","-",Settings!C19) | G11: =IF(Settings!C20="","-",Settings!C20) | H11: =IF(Settings!C21="","-",Settings!C21) | I11: =IF(Settings!C22="","-",Settings!C22) | J11: =IF(Settings!C23="","-",Settings!C23) | K11: =IF(Settings!C24="","-",Settings!C24) | L11: =IF(Settings!C25="","-",Settings!C25) | M11: =IF(Settings!C26="","-",Settings!C26)
A12: LSL | D12: =IF(Settings!D17="","-",Settings!D17) | E12: =IF(Settings!D18="","-",Settings!D18) | F12: =IF(Settings!D19="","-",Settings!D19) | G12: =IF(Settings!D20="","-",Settings!D20) | H12: =IF(Settings!D21="","-",Settings!D21) | I12: =IF(Settings!D22="","-",Settings!D22) | J12: =IF(Settings!D23="","-",Settings!D23) | K12: =IF(Settings!D24="","-",Settings!D24) | L12: =IF(Settings!D25="","-",Settings!D25) | M12: =IF(Settings!D26="","-",Settings!D26)
A13: USL | D13: =IF(Settings!E17="","-",Settings!E17) | E13: =IF(Settings!E18="","-",Settings!E18) | F13: =IF(Settings!E19="","-",Settings!E19) | G13: =IF(Settings!E20="","-",Settings!E20) | H13: =IF(Settings!E21="","-",Settings!E21) | I13: =IF(Settings!E22="","-",Settings!E22) | J13: =IF(Settings!E23="","-",Settings!E23) | K13: =IF(Settings!E24="","-",Settings!E24) | L13: =IF(Settings!E25="","-",Settings!E25) | M13: =IF(Settings!E26="","-",Settings!E26)
A14: Unit | D14: =IF(Settings!F17="","-",Settings!F17) | E14: =IF(Settings!F18="","-",Settings!F18) | F14: =IF(Settings!F19="","-",Settings!F19) | G14: =IF(Settings!F20="","-",Settings!F20) | H14: =IF(Settings!F21="","-",Settings!F21) | I14: =IF(Settings!F22="","-",Settings!F22) | J14: =IF(Settings!F23="","-",Settings!F23) | K14: =IF(Settings!F24="","-",Settings!F24) | L14: =IF(Settings!F25="","-",Settings!F25) | M14: =IF(Settings!F26="","-",Settings!F26)
A16: Sample # | B16: Time | C16: Serial / Batch | D16: Char 1 | E16: Char 2 | F16: Char 3 | G16: Char 4 | H16: Char 5 | I16: Char 6 | J16: Char 7 | K16: Char 8 | L16: Char 9 | M16: Char 10 | N16: Notes
A17: 1
A18: 2
A19: 3
A20: 4
A21: 5
A22: 6
A23: 7
A24: 8
A25: 9
A26: 10
A27: 11
A28: 12
... A41: 25
A43: Notes / out-of-spec actions:
A48: Recorded by: | D48: Signature: | G48: Checked by: | J48: Date:
A50: Transfer readings into the Data Entry sheet (Char 1 -> column H, Char 2 -> column I, ...). Keep this sheet with the job pack.

Sheet Control Charts
